Workbook

Sheet pollution_tolerance
A1: Group | B1: Taxa | C1: Level | D1: IBMWP_score | E1: dispersal
A2: Aracnidos | B2: Acariformes | C2: superorder | D2: 4
A3: Coleoptera | B3: Chrysomelidae | C3: family | D3: 4
A4: Coleoptera | B4: Curculionidae | C4: family | D4: 4
A5: Coleoptera | B5: Dryopidae | C5: family | D5: 5
A6: Coleoptera | B6: Dytiscidae | C6: family | D6: 3
A7: Coleoptera | B7: Elmidae | C7: family | D7: 5
A8: Coleoptera | B8: Gyrinidae | C8: family | D8: 3
A9: Coleoptera | B9: Haliplidae | C9: family | D9: 4
A10: Coleoptera | B10: Helophoridae | C10: family | D10: 5
A11: Coleoptera | B11: Hydraenidae | C11: family | D11: 5
A12: Coleoptera | B12: Hydrochidae | C12: family | D12: 5
A13: Coleoptera | B13: Hydrophilidae | C13: family | D13: 3
... A126: Turbellaria | B126: Planariidae | C126: family | D126: 5

Sheet dispersal_strategy
A1: Taxa | B1: Level | C1: done
A2: Acariformes | B2: superorder | C2: no
A3: Chrysomelidae | B3: family | C3: ok
A4: Curculionidae | B4: family | C4: no
A5: Dryopidae | B5: family | C5: ok
A6: Dytiscidae | B6: family | C6: ok
A7: Elmidae | B7: family | C7: ok
A8: Gyrinidae | B8: family | C8: ok
A9: Haliplidae | B9: family | C9: ok
A10: Helophoridae | B10: family | C10: ok
A11: Hydraenidae | B11: family | C11: ok
A12: Hydrochidae | B12: family | C12: ok
... A126: Planariidae | B126: family | C126: ok

Sheet dispersal_strategy_family
C1: Aquatic passive | D1: Aquatic active | E1: Aerial passive | F1: Aerial active
A2: Family | B2: Genus | C2: dis1 | D2: dis2 | E2: dis3 | F2: dis4
A3: Chrysomelidae | B3: Donacia | C3: 0 | D3: 0 | E3: 0 | F3: 3
A4: Chrysomelidae | B4: Macroplea | C4: 0 | D4: 1 | E4: 0 | F4: 3
A5: Chrysomelidae | B5: Plateumaris | C5: 0 | D5: 1 | E5: 0 | F5: 3
A6: Dryopidae | B6: Dryops | C6: 0 | D6: 1 | E6: 0 | F6: 3
A7: Dryopidae | B7: Pomatinus | C7: 0 | D7: 1 | E7: 0 | F7: 3
A8: Dytiscidae | B8: Acilius | C8: 0 | D8: 1 | E8: 0 | F8: 3
A9: Dytiscidae | B9: Agabus | C9: 1 | D9: 1 | E9: 0 | F9: 3
A10: Dytiscidae | B10: Bidessus | C10: 1 | D10: 1 | E10: 0 | F10: 3
A11: Dytiscidae | B11: Boreonectes | C11: 0 | D11: 1 | E11: 0 | F11: 3
A12: Dytiscidae | B12: Clemnius | C12: 0 | D12: 1 | E12: 0 | F12: 3
A13: Dytiscidae | B13: Colymbetes | C13: 0 | D13: 1 | E13: 0 | F13: 3
A14: Dytiscidae | B14: Cybister | C14: 0 | D14: 1 | E14: 0 | F14: 3
... A148: Baetidae | B148: Baetis | C148: 3 | D148: 2 | E148: 1 | F148: 3
A149: Baetidae | B149: Pseudocentroptiloides | C149: NA | D149: NA | E149: NA | F149: NA
A150: Baetidae | B150: Centroptilum | C150: 2 | D150: 2 | E150: 1 | F150: 2
A151: Baetidae | B151: Cloeon | C151: 1 | D151: 2 | E151: 1 | F151: 2
A152: Baetidae | B152: Nigrobaetis | C152: 2 | D152: 1,75 | E152: 1 | F152: 2,25
A153: Baetidae | B153: Procloeon | C153: 1 | D153: 2 | E153: 1 | F153: 2
A154: Baetidae | B154: Pseudocentroptilum | C154: 2 | D154: 2 | E154: 1 | F154: 2
A155: Caenidae | B155: Brachycercus | C155: 1 | D155: 1 | E155: 1 | F155: 1
A156: Caenidae | B156: Caenis | C156: 2 | D156: 1 | E156: 1 | F156: 1
A157: Ephemerellidae | B157: Ephemerella | C157: 2 | D157: 3 | E157: 1 | F157: 3
A158: Ephemerellidae | B158: Torleya | C158: 2 | D158: 1 | E158: 1 | F158: 2
A159: Ephemeridae | B159: Ephemera | C159: 1 | D159: 1 | E159: 1 | F159: 3
A160: Heptageniidae | B160: Afronurus | C160: 3 | D160: 1 | E160: 1 | F160: 3
A161: Heptageniidae | B161: Ecdyonurus | C161: 3 | D161: 1 | E161: 1 | F161: 3
A162: Heptageniidae | B162: Electrogena | C162: 3 | D162: 1 | E162: 1 | F162: 3
A163: Heptageniidae | B163: Epeorus | C163: 2 | D163: 1 | E163: 1 | F163: 3
A164: Heptageniidae | B164: Heptagenia | C164: 3 | D164: 1 | E164: 1 | F164: 3
... A190: Gerridae | B190: Gerris | C190: 1 | D190: 2 | E190: 0 | F190: 3
A191: Gerridae | B191: Limnoporus | C191: NA | D191: NA | E191: NA | F191: NA
A192: Hydrometridae | B192: Hydrometra | C192: 1 | D192: 3 | E192: 0 | F192: 1
A193: Mesoveliidae | B193: Mesovelia | C193: 0 | D193: 2 | E193: 0 | F193: 1
A194: Naucoridae | B194: Ilyocoris | C194: 0 | D194: 3 | E194: 0 | F194: 3
A195: Naucoridae | B195: Naucoris | C195: 1 | D195: 3 | E195: 0 | F195: 2
A196: Nepidae | B196: Nepa | C196: 1 | D196: 3 | E196: 0 | F196: 2
A197: Nepidae | B197: Ranatra | C197: 1 | D197: 3 | E197: 0 | F197: 2
A198: Notonectidae | B198: Anisops | C198: 0 | D198: 2 | E198: 0 | F198: 3
...

Sheet Pivot Table 1

Sheet av_family
B1: Aquatic passive | C1: Aquatic active | D1: Aerial passive | E1: Aerial active
A2: Family | B2: dis1 | C2: dis2 | D2: dis3 | E2: dis4
A3: Acariformes | B3: NA | C3: NA | D3: NA | E3: NA
A4: Aeshnidae | B4: 1 | C4: 0.8 | D4: 0 | E4: 2.8
A5: Ancylidae | B5: 2 | C5: 1 | D5: 1 | E5: 0
A6: Anthomyiidae | B6: 0 | C6: 1 | D6: 0 | E6: 0
A7: Aphelocheiridae | B7: 3 | C7: 3 | D7: 0 | E7: 0
A8: Asellidae | B8: 3 | C8: 0 | D8: 0 | E8: 0
A9: Astacidae | B9: 0 | C9: 2 | D9: 0 | E9: 0
A10: Athericidae | B10: 0.33333333 | C10: 1 | D10: 0 | E10: 1
A11: Atyidae | B11: 1 | C11: 1 | D11: 0 | E11: 0
A12: Baetidae | B12: 1.875 | C12: 1.7142857 | D12: 1 | E12: 2.1428571
A13: Beraeidae | B13: 0 | C13: 1 | D13: 1 | E13: 1
A14: Bithyniidae | B14: 2 | C14: 1 | D14: 0 | E14: 0
A15: Blephariceridae | B15: 2 | C15: 1 | D15: 0 | E15: 1
... A31: Culicidae | B31: 0 | C31: 0 | D31: 2 | E31: 3
A32: Curculionidae | B32: NA | C32: NA | D32: NA | E32: NA
A33: Dendrocoelidae | B33: 0 | C33: 3 | D33: 0 | E33: 0
A34: Dixidae | B34: 3 | C34: 1 | D34: 1 | E34: 0
A35: Dolichopodidae | B35: 0 | C35: 0 | D35: 1 | E35: 1
A36: Dryopidae | B36: 0 | C36: 1 | D36: 0 | E36: 3
A37: Dugesiidae | B37: 0 | C37: 2 | D37: 0 | E37: 0
A38: Dytiscidae | B38: 0.54761905 | C38: 1.0238095 | D38: 0 | E38: 2.7857143
A39: Ecnomidae | B39: 1 | C39: 1 | D39: 1 | E39: 1
A40: Elmidae | B40: 1.8181818 | C40: 1 | D40: 0 | E40: 2.0909091
A41: Empididae | B41: 1 | C41: 1 | D41: 0 | E41: 2
A42: Ephemerellidae | B42: 2 | C42: 2 | D42: 1 | E42: 2.5
A43: Ephemeridae | B43: 1 | C43: 1 | D43: 1 | E43: 3
A44: Ephydridae | B44: 0 | C44: 0 | D44: 0 | E44: 1
... A83: Odontoceridae | B83: 3 | C83: 1 | D83: 1 | E83: 2
A84: Oligocheta | B84: NA | C84: NA | D84: NA | E84: NA
A85: Oligoneuriidae | B85: 3 | C85: 1 | D85: 1 | E85: 2
A86: Ostracoda | B86: NA | C86: NA | D86: NA | E86: NA
A87: Palaemonidae | B87: 3 | C87: 3 | D87: 0 | E87: 0
A88: Perlidae | B88: 1 | C88: 2 | D88: 0 | E88: 1
A89: Perlodidae | B89: 1.3333333 | C89: 1.8888889 | D89: 0.11111111 | E89: 1.2222222
A90: Philopotamidae | B90: 1 | C90: 1.3333333 | D90: 1 | E90: 1
A91: Phryganeidae | B91: 0.66666667 | C91: 2.1666667 | D91: 1 | E91: 2.2
A92: Physidae | B92: 2 | C92: 1 | D92: 0 | E92: 0
A93: Piscicolidae | B93: 3 | C93: 2 | D93: 0 | E93: 0
...

Sheet av_family_updated
B1: Aquatic passive | C1: Aquatic active | D1: Aerial active
A2: Family | B2: dis1 | C2: dis2 | D2: dis4 | E2: dispersal_strategy | F2: IBMWP_score
A3: Acariformes | B3: NA | C3: NA | D3: NA | E3: NA | F3: =VLOOKUP(A3, pollution_tolerance!$B$2:$S$126, 3, FALSE) -> 4
A4: Aeshnidae | B4: 1 | C4: 0.8 | D4: 2.8 | E4: dis4 | F4: =VLOOKUP(A4, pollution_tolerance!$B$2:$S$126, 3, FALSE) -> 8
A5: Ancylidae | B5: 2 | C5: 1 | D5: 0 | E5: dis1 | F5: =VLOOKUP(A5, pollution_tolerance!$B$2:$S$126, 3, FALSE) -> 6
A6: Anthomyiidae | B6: 0 | C6: 1 | D6: 0 | E6: dis2 | F6: =VLOOKUP(A6, pollution_tolerance!$B$2:$S$126, 3, FALSE) -> 4
A7: Aphelocheiridae | B7: 3 | C7: 3 | D7: 0 | E7: dis1 | F7: =VLOOKUP(A7, pollution_tolerance!$B$2:$S$126, 3, FALSE) -> 10
A8: Aphelocheiridae | B8: 3 | C8: 3 | D8: 0 | E8: dis2 | F8: =VLOOKUP(A8, pollution_tolerance!$B$2:$S$126, 3, FALSE) -> 10
A9: Asellidae | B9: 3 | C9: 0 | D9: 0 | E9: dis1 | F9: =VLOOKUP(A9, pollution_tolerance!$B$2:$S$126, 3, FALSE) -> 3
A10: Astacidae | B10: 0 | C10: 2 | D10: 0 | E10: dis2 | F10: =VLOOKUP(A10, pollution_tolerance!$B$2:$S$126, 3, FALSE) -> 8
A11: Athericidae | B11: 0.33333333 | C11: 1 | D11: 1 | E11: dis2 | F11: =VLOOKUP(A11, pollution_tolerance!$B$2:$S$126, 3, FALSE) -> 10
A12: Athericidae | B12: 0.33333333 | C12: 1 | D12: 1 | E12: dis4 | F12: =VLOOKUP(A12, pollution_tolerance!$B$2:$S$126, 3, FALSE) -> 10
A13: Atyidae | B13: 1 | C13: 1 | D13: 0 | E13: dis1 | F13: =VLOOKUP(A13, pollution_tolerance!$B$2:$S$126, 3, FALSE) -> 6
A14: Atyidae | B14: 1 | C14: 1 | D14: 0 | E14: dis2 | F14: =VLOOKUP(A14, pollution_tolerance!$B$2:$S$126, 3, FALSE) -> 6
A15: Baetidae | B15: 1.875 | C15: 1.7142857 | D15: 2.1428571 | E15: dis1 | F15: =VLOOKUP(A15, pollution_tolerance!$B$2:$S$126, 3, FALSE) -> 4
... A43: Culicidae | B43: 0 | C43: 0 | D43: 3 | E43: dis4 | F43: =VLOOKUP(A43, pollution_tolerance!$B$2:$S$126, 3, FALSE) -> 2
A44: Curculionidae | B44: NA | C44: NA | D44: NA | E44: NA | F44: =VLOOKUP(A44, pollution_tolerance!$B$2:$S$126, 3, FALSE) -> 4
A45: Dendrocoelidae | B45: 0 | C45: 3 | D45: 0 | E45: dis2 | F45: =VLOOKUP(A45, pollution_tolerance!$B$2:$S$126, 3, FALSE) -> 5
A46: Dixidae | B46: 3 | C46: 1 | D46: 0 | E46: dis1 | F46: =VLOOKUP(A46, pollution_tolerance!$B$2:$S$126, 3, FALSE) -> 4
A47: Dolichopodidae | B47: 0 | C47: 0 | D47: 1 | E47: dis4 | F47: =VLOOKUP(A47, pollution_tolerance!$B$2:$S$126, 3, FALSE) -> 4
A48: Dryopidae | B48: 0 | C48: 1 | D48: 3 | E48: dis4 | F48: =VLOOKUP(A48, pollution_tolerance!$B$2:$S$126, 3, FALSE) -> 5
A49: Dugesiidae | B49: 0 | C49: 2 | D49: 0 | E49: dis2 | F49: =VLOOKUP(A49, pollution_tolerance!$B$2:$S$126, 3, FALSE) -> 5
A50: Dytiscidae | B50: 0.54761905 | C50: 1.0238095 | D50: 2.7857143 | E50: dis4 | F50: =VLOOKUP(A50, pollution_tolerance!$B$2:$S$126, 3, FALSE) -> 3
A51: Ecnomidae | B51: 1 | C51: 1 | D51: 1 | E51: dis1 | F51: =VLOOKUP(A51, pollution_tolerance!$B$2:$S$126, 3, FALSE) -> 7
A52: Ecnomidae | B52: 1 | C52: 1 | D52: 1 | E52: dis2 | F52: =VLOOKUP(A52, pollution_tolerance!$B$2:$S$126, 3, FALSE) -> 7
A53: Ecnomidae | B53: 1 | C53: 1 | D53: 1 | E53: dis4 | F53: =VLOOKUP(A53, pollution_tolerance!$B$2:$S$126, 3, FALSE) -> 7
A54: Elmidae | B54: 1.8181818 | C54: 1 | D54: 2.0909091 | E54: dis1 | F54: =VLOOKUP(A54, pollution_tolerance!$B$2:$S$126, 3, FALSE) -> 5
A55: Elmidae | B55: 1.8181818 | C55: 1 | D55: 2.0909091 | E55: dis4 | F55: =VLOOKUP(A55, pollution_tolerance!$B$2:$S$126, 3, FALSE) -> 5
A56: Empididae | B56: 1 | C56: 1 | D56: 2 | E56: dis4 | F56: =VLOOKUP(A56, pollution_tolerance!$B$2:$S$126, 3, FALSE) -> 4
... A122: Odontoceridae | B122: 3 | C122: 1 | D122: 2 | E122: dis4 | F122: =VLOOKUP(A122, pollution_tolerance!$B$2:$S$126, 3, FALSE) -> 10
A123: Oligocheta | B123: NA | C123: NA | D123: NA | E123: NA | F123: =VLOOKUP(A123, pollution_tolerance!$B$2:$S$126, 3, FALSE) -> 1
A124: Oligoneuriidae | B124: 3 | C124: 1 | D124: 2 | E124: dis1 | F124: =VLOOKUP(A124, pollution_tolerance!$B$2:$S$126, 3, FALSE) -> 5
A125: Oligoneuriidae | B125: 3 | C125: 1 | D125: 2 | E125: dis4 | F125: =VLOOKUP(A125, pollution_tolerance!$B$2:$S$126, 3, FALSE) -> 5
A126: Ostracoda | B126: NA | C126: NA | D126: NA | E126: NA | F126: =VLOOKUP(A126, pollution_tolerance!$B$2:$S$126, 3, FALSE) -> 3
A127: Palaemonidae | B127: 3 | C127: 3 | D127: 0 | E127: dis1 | F127: =VLOOKUP(A127, pollution_tolerance!$B$2:$S$126, 3, FALSE) -> 6
A128: Palaemonidae | B128: 3 | C128: 3 | D128: 0 | E128: dis2 | F128: =VLOOKUP(A128, pollution_tolerance!$B$2:$S$126, 3, FALSE) -> 6
A129: Perlidae | B129: 1 | C129: 2 | D129: 1 | E129: dis2 | F129: =VLOOKUP(A129, pollution_tolerance!$B$2:$S$126, 3, FALSE) -> 10
A130: Perlodidae | B130: 1.3333333 | C130: 1.8888889 | D130: 1.2222222 | E130: dis2 | F130: =VLOOKUP(A130, pollution_tolerance!$B$2:$S$126, 3, FALSE) -> 10
A131: Perlodidae | B131: 1.3333333 | C131: 1.8888889 | D131: 1.2222222 | E131: dis1 | F131: =VLOOKUP(A131, pollution_tolerance!$B$2:$S$126, 3, FALSE) -> 10
A132: Philopotamidae | B132: 1 | C132: 1.3333333 | D132: 1 | E132: dis1 | F132: =VLOOKUP(A132, pollution_tolerance!$B$2:$S$126, 3, FALSE) -> 8
...

Sheet final
A1: Family | B1: dispersal_strategy | C1: IBMWP_score
A2: Acariformes | B2: NA | C2: 4
A3: Aeshnidae | B3: dis4 | C3: 8
A4: Ancylidae | B4: dis1 | C4: 6
A5: Anthomyiidae | B5: dis2 | C5: 4
A6: Aphelocheiridae | B6: dis1 | C6: 10
A7: Aphelocheiridae | B7: dis2 | C7: 10
A8: Asellidae | B8: dis1 | C8: 3
A9: Astacidae | B9: dis2 | C9: 8
A10: Athericidae | B10: dis2 | C10: 10
A11: Athericidae | B11: dis4 | C11: 10
A12: Atyidae | B12: dis1 | C12: 6
A13: Atyidae | B13: dis2 | C13: 6
... A188: Viviparidae | B188: dis1 | C188: 6
A189: mean
A190: median
